# try...catch와 에러 핸들링

아무리 프로그래밍에 능한 개발자라도 에러가 있는 코드를 작성할 수 있다. 개발자가 아무리 완벽한 코드를 작성해도 실수가 있을 수 있고 여러 외부 요인(사용자의 잘못 된 값 입력, 데이터 통신 오류 등)이 있기 때문에 항상 개발자는 작성한 코드가 에러로 인해 중단되지 않도록 여러 해결책을 만들어야 한다.

이런 모든 에러를 예측하고 `if/else`문을 사용해 예외 처리를 할 수도 있지만 개발자가 모든 에러를 예측하기는 쉽지 않다. 그리고 가독성 또한 낮아진다.

그렇기에 `try...catch`문을 활용해 코드가 중단되는 것을 방지하고 에러에 대한 예외처리 등을 작성하면 좀 더 안정적인 코드를 작성할 수 있다.

## try...catch

말 그대로 try(시도)해서 에러가 생기면 catch(잡는) 문법이다. 그렇기 때문에 `try`와 `catch`라는 두 개의 주요 블록으로 구성된다.

```jsx
try {
	// 실행될 코드
} catch (error) {
	// 에러 발생 시 실행할 코드
}
```

`try...catch` 동작 알고리즘은 다음과 같다.

1. 먼저 `try{...}`안의 코드가 실행된다.
2. 에러가 없다면, `try`안의 마지막 줄까지 실행되고, `catch`블록은 건너 뛴다.
3. 에러가 있다면, `try`안 코드의 실행이 중단되고, `catch(error)`블록으로 제어 흐름이 넘어가며 변수 `error`는 무슨 일이 일어났는지에 대한 정보가 담긴 에러 객체를 반환한다.

이렇게 `try{...}`블록 안에서 에러가 발생하더라도 `catch`문으로 흐름이 넘어가며 에러를 처리하기 때문에 실행중인 코드가 중단되지 않는다.

그렇다면 `try...catch`는 모든 에러를 처리할까? 아니다.  `try...catch`는 모든 에러를 처리해주는 만능 에러 핸들러는 아니다. 몇가지 예외가 있다.

### try...catch는 오직 런타임 에러에만 동작한다.

`try...catch`는 실행 가능한 코드에서만 동작한다. 즉, 문법적으로 유효한 자바스크립트 코드에서만 동작한다. 문법적으로 에러가 있다면 자바스크립트 코드 자체가 실행되지 않을테니 어찌보면 당연한 구조이다.

```jsx
try {
	// parse-time error
	{/=234..
} catch (error) {
	console.error(error);
}
```

자바스크립트 엔진은 코드를 모두 읽고 난 후 코드를 실행한다. 코드를 읽는 도중 발생한 에러는 'parse-time 에러'라고 부르는데, 엔진은 이 코드를 이해할 수 없기 때문에 parse-time 에러는 코드 안에서 복구가 불가능하다.

`try...catch`는 유효한 코드에서 발생하는 에러만 처리할 수 있다. 이런 에러를 '런타임 에러(runtime error)' 혹은 '예외(exception)'라고 부른다.

### try...catch는 동기적으로 동작한다.

`setTimeout`이나 `Promise`처럼 비동기적으로 동작하는 코드에서 발생한 에러는 `try...catch`에서 잡아낼 수 없다.

```jsx
try {
  setTimeout(() => {
    noSuchVariable;
  }, 1000);
} catch (error) {
  console.error('에러 발생!');
}
```

`setTimeout`에 넘겨진 함수는 엔진이 `try...catch`문을 벗어난 뒤 실행되기 때문에 비동기적으로 동작하는 코드 내부에 `try...catch`문을 구현해야 한다.

```jsx
// 에러 발생!
setTimeout(() => {
  try {
    noSuchVariable;
  } catch (error) {
    console.error('에러 발생!');
  }
}, 1000);
```

### 에러 객체

`try`블록에서 에러가 발생하면 자바스크립트는 에러에 대한 데이터를 담은 객체를 생성한다. 그리고 `catch`블록에 이 객체를 인자로 전달한다.

```jsx
try {
	// 실행될 코드
} catch (error) { // <- 생성된 에러 객체, 다른 이름으로도 선언 가능
	// 에러 발생 시 실행할 코드
}
```

내장 에러 전체와 에러 객체는 두 가지 주요 프로퍼티를 가진다.

- `name`: 에러 이름, 정의도지 않은 변수 때문에 발생한 에러라면 `ReferenceError`가 이름이 된다.
- `message`: 에러 상세 내용을 담고 있는 문자 메시지

표준은 아니지만 `name`과 `message`이외에 대부분의 호스트 환경에서 지원하는 프로퍼티도 있다. `stack`은 가장 널리 사용되는 비 표준 프로퍼티 중 하나로 현재 호출 스택, 에러를 유발한 중첩 호출들의 순서 정보를 가진 문자열이다. 보통 디버깅 목적으로 사용된다.

### 선택적 catch 바인딩

에러에 대한 자세한 정보가 필요하지 않다면 `catch`에서 이를 생략할 수 있다.

```jsx
try {
	// 실행될 코드
} catch { 
	// 에러 발생 시 실행할 코드
}
```

### 직접 에러를 만들어 던지기

문법이 잘못되지 않았지만, 코드 내에서 직접 에러를 발생시켜줘야 할 상황도 있다.

```jsx
const json = '{ "name": "chanyeong" }';

try {
  const user = JSON.parse(json);
  console.log(user.job);
} catch (error) {
  console.error('error');
}
```

다음 코드에서 `JSON.parse`는 정상적으로 작동 하지만 `user`객체에 `job`프로퍼티가 없기 때문에 개발자가 의도한 상황이 아니다. 이런 경우 에러를 발생해야 하지만 자바스크립트에서는 `undefined`를 출력해 에러가 발생하지 않는다.

```jsx
const json = '{ "name": "chanyeong" }';

try {
  const user = JSON.parse(json);
  if (!user.job) {
    throw new Error('해당 프로퍼티가 존재하지 않습니다.');
  }
  console.log(user.job);
} catch (error) {
  // 해당 프로퍼티가 존재하지 않습니다.
  console.error(error.message);
}
```

그렇다면 `throw`연산자를 사용해 직접 에러를 생성할 수 도 있다. 다음 코드는 `user.job`이 없는지 확인해서 `throw`연산자를 사용해 인자로 넣어준 메시지를 가진 에러를 생성해줬다.

```jsx
throw <error object>
```

문법은 다음과 같다. 이론적으로는 숫자, 문자열과 같은 원시형 자료를 포함한 어떤 것이든 에러 객체로 사용할 수 있지만 내장 에러와의 호환을 위해 되도록 에러 객체에 `name`과 `message`프로퍼티를 넣어주는 것을 권장한다.

자바스크립트는 `Error`, `SyntaxError`, `ReferenceError`, `TypeError`등의 표준 에러 객체 관련 생성자를 지원한다. 이 생성자를 이용해 아래와 같이 에러 객체를 만들 수 도 있다.

```jsx
const error = new Error('message');
const syntaxError = new SyntaxError('message');
const referenceError = new ReferenceError('message');

console.log(referenceError.name); // ReferenceError
console.log(referenceError.message); // 'message'
```

일반 객체가 아닌 내장 생성자를 사용해 만든 내장 에러 객체의 `name`프로퍼티는 생성자 이름과 동일한 값을 갖으며 인자로 넣어준 문자열은 `message`프로퍼티가 갖는다.

### try...catch...finally

에러 핸들링은 `try...catch`뿐만 아니라 `finally`라는 코드 블럭을 하나 더 가질 수 있다. `finally`는 `try...catch`의 에러가 `catch`되던 에러 없이 `try`문이 끝나는 것과 상관 없이 무조건 `try...catch`가 종료 후에 실행 되는 블럭이다.

```jsx
try {
  // 실행될 코드
} catch (error) {
  // 에러 발생 시 실행할 코드
} finally {
  // try블럭 또는 catch블럭 실행 후 무조건 실행
}
```

`try...catch`...finally 동작 알고리즘은 다음과 같다.

1. 먼저 `try{...}`안의 코드가 실행된다.
2. 에러가 없다면, `try`안의 마지막 줄까지 실행되고, `catch`블록은 건너 뛴뒤 `finally`블록이 실행된다.
3. 에러가 있다면, `try`안 코드의 실행이 중단되고, `catch(error)`블록으로 제어 흐름이 넘어가며 변수 `error`는 무슨 일이 일어났는지에 대한 정보가 담긴 에러 객체를 반환한뒤 `finally`블록이 실행된다.

`finally`절은 무언가를 실행하고, 실행 결과에 상관 없이 실행을 완료하고 싶을 경우 사용한다. `try`나 `catch`문에서 `return`으로 강제로 블록을 종료시킨다고 해도 `finally`는 실행된다.

`finally`는 `catch`절이 없는 `try...finally`도 유용하게 사용할 수 있다. 에러를 처리하고 싶지 않지만, 시작한 작업이 마무리 되었는지 확실히 하고 싶은 경우에 사용한다.